<testng-results>
  <reporter-output>
  </reporter-output>
  <suite name="blog">
    <groups>
    </groups>
    <test name="com.pillartech.blog.LoginServiceTest">
      <class name="com.pillartech.blog.LoginServiceTest">
        <test-method status="PASS" signature="setupMocksAndTargetForDefaultBehavior()" name="setupMocksAndTargetForDefaultBehavior" is-config="true" duration-ms="205" started-at="2010-02-08T15:37:27Z" finished-at="2010-02-08T15:37:27Z">
        </test-method>
        <test-method status="PASS" signature="shouldInactivateAfterThreeFailedPasswords()" name="shouldInactivateAfterThreeFailedPasswords" duration-ms="16" started-at="2010-02-08T15:37:27Z" finished-at="2010-02-08T15:37:27Z">
        </test-method>
        <test-method status="PASS" signature="setupMocksAndTargetForDefaultBehavior()" name="setupMocksAndTargetForDefaultBehavior" is-config="true" duration-ms="1" started-at="2010-02-08T15:37:27Z" finished-at="2010-02-08T15:37:27Z">
        </test-method>
        <test-method status="PASS" signature="shouldLoginValidPasswords()" name="shouldLoginValidPasswords" duration-ms="7" started-at="2010-02-08T15:37:27Z" finished-at="2010-02-08T15:37:27Z">
        </test-method>
        <test-method status="PASS" signature="setupMocksAndTargetForDefaultBehavior()" name="setupMocksAndTargetForDefaultBehavior" is-config="true" duration-ms="2" started-at="2010-02-08T15:37:28Z" finished-at="2010-02-08T15:37:28Z">
        </test-method>
        <test-method status="PASS" signature="shouldNotInactivateUsersAfterThreeTotalFailedPasswords_CustomMatcherApproach()" name="shouldNotInactivateUsersAfterThreeTotalFailedPasswords_CustomMatcherApproach" duration-ms="6" started-at="2010-02-08T15:37:28Z" finished-at="2010-02-08T15:37:28Z">
        </test-method>
        <test-method status="PASS" signature="setupMocksAndTargetForDefaultBehavior()" name="setupMocksAndTargetForDefaultBehavior" is-config="true" duration-ms="1" started-at="2010-02-08T15:37:28Z" finished-at="2010-02-08T15:37:28Z">
        </test-method>
        <test-method status="PASS" signature="shouldNotInactivateUsersAfterThreeTotalFailedPasswords_RepetitiveApproach()" name="shouldNotInactivateUsersAfterThreeTotalFailedPasswords_RepetitiveApproach" duration-ms="6" started-at="2010-02-08T15:37:28Z" finished-at="2010-02-08T15:37:28Z">
        </test-method>
        <test-method status="PASS" signature="setupMocksAndTargetForDefaultBehavior()" name="setupMocksAndTargetForDefaultBehavior" is-config="true" duration-ms="1" started-at="2010-02-08T15:37:28Z" finished-at="2010-02-08T15:37:28Z">
        </test-method>
        <test-method status="PASS" signature="shouldNotLoginBadPasswords()" name="shouldNotLoginBadPasswords" duration-ms="3" started-at="2010-02-08T15:37:28Z" finished-at="2010-02-08T15:37:28Z">
        </test-method>
        <test-method status="PASS" signature="setupMocksAndTargetForDefaultBehavior()" name="setupMocksAndTargetForDefaultBehavior" is-config="true" duration-ms="1" started-at="2010-02-08T15:37:28Z" finished-at="2010-02-08T15:37:28Z">
        </test-method>
        <test-method status="PASS" signature="shouldThrowAnExceptionIfAccountIsInactive()" name="shouldThrowAnExceptionIfAccountIsInactive" duration-ms="4" started-at="2010-02-08T15:37:28Z" finished-at="2010-02-08T15:37:28Z">
          <exception class="com.pillartech.blog.exception.AccountRevokedException">
            <message>
              <![CDATA[Account has been revoked for too many failed login attempts.]]>
            </message>
            <full-stacktrace>
              <![CDATA[com.pillartech.blog.exception.AccountRevokedException: Account has been revoked for too many failed login attempts.
	at com.pillartech.blog.LoginServiceImpl.login(LoginServiceImpl.java:25)
	at com.pillartech.blog.LoginServiceTest.shouldThrowAnExceptionIfAccountIsInactive(LoginServiceTest.java:143)
	at sun.reflect.NativeMethodAccessorImpl.invoke0(Native Method)
	at sun.reflect.NativeMethodAccessorImpl.invoke(NativeMethodAccessorImpl.java:39)
	at sun.reflect.DelegatingMethodAccessorImpl.invoke(DelegatingMethodAccessorImpl.java:25)
	at java.lang.reflect.Method.invoke(Method.java:597)
	at org.testng.internal.MethodHelper.invokeMethod(MethodHelper.java:644)
	at org.testng.internal.Invoker.invokeMethod(Invoker.java:546)
	at org.testng.internal.Invoker.invokeTestMethod(Invoker.java:700)
	at org.testng.internal.Invoker.invokeTestMethods(Invoker.java:1002)
	at org.testng.internal.TestMethodWorker.invokeTestMethods(TestMethodWorker.java:137)
	at org.testng.internal.TestMethodWorker.run(TestMethodWorker.java:121)
	at org.testng.TestRunner.runWorkers(TestRunner.java:908)
	at org.testng.TestRunner.privateRun(TestRunner.java:617)
	at org.testng.TestRunner.run(TestRunner.java:498)
	at org.testng.SuiteRunner.runTest(SuiteRunner.java:329)
	at org.testng.SuiteRunner.runSequentially(SuiteRunner.java:324)
	at org.testng.SuiteRunner.privateRun(SuiteRunner.java:296)
	at org.testng.SuiteRunner.run(SuiteRunner.java:201)
	at org.testng.TestNG.createAndRunSuiteRunners(TestNG.java:915)
	at org.testng.TestNG.runSuitesLocally(TestNG.java:879)
	at org.testng.TestNG.run(TestNG.java:787)
	at org.testng.remote.RemoteTestNG.run(RemoteTestNG.java:75)
	at org.testng.remote.RemoteTestNG.main(RemoteTestNG.java:127)
]]>
            </full-stacktrace>
          </exception>
        </test-method>
        <test-method status="PASS" signature="setupMocksAndTargetForDefaultBehavior()" name="setupMocksAndTargetForDefaultBehavior" is-config="true" duration-ms="1" started-at="2010-02-08T15:37:28Z" finished-at="2010-02-08T15:37:28Z">
        </test-method>
        <test-method status="PASS" signature="shouldThrowAnExceptionIfAccountIsNotFound()" name="shouldThrowAnExceptionIfAccountIsNotFound" duration-ms="3" started-at="2010-02-08T15:37:28Z" finished-at="2010-02-08T15:37:28Z">
          <exception class="com.pillartech.blog.exception.AccountNotFoundException">
            <message>
              <![CDATA[Account with username todd was not found.]]>
            </message>
            <full-stacktrace>
              <![CDATA[com.pillartech.blog.exception.AccountNotFoundException: Account with username todd was not found.
	at com.pillartech.blog.LoginServiceImpl.findAccountByUsername(LoginServiceImpl.java:43)
	at com.pillartech.blog.LoginServiceImpl.login(LoginServiceImpl.java:22)
	at com.pillartech.blog.LoginServiceTest.shouldThrowAnExceptionIfAccountIsNotFound(LoginServiceTest.java:134)
	at sun.reflect.NativeMethodAccessorImpl.invoke0(Native Method)
	at sun.reflect.NativeMethodAccessorImpl.invoke(NativeMethodAccessorImpl.java:39)
	at sun.reflect.DelegatingMethodAccessorImpl.invoke(DelegatingMethodAccessorImpl.java:25)
	at java.lang.reflect.Method.invoke(Method.java:597)
	at org.testng.internal.MethodHelper.invokeMethod(MethodHelper.java:644)
	at org.testng.internal.Invoker.invokeMethod(Invoker.java:546)
	at org.testng.internal.Invoker.invokeTestMethod(Invoker.java:700)
	at org.testng.internal.Invoker.invokeTestMethods(Invoker.java:1002)
	at org.testng.internal.TestMethodWorker.invokeTestMethods(TestMethodWorker.java:137)
	at org.testng.internal.TestMethodWorker.run(TestMethodWorker.java:121)
	at org.testng.TestRunner.runWorkers(TestRunner.java:908)
	at org.testng.TestRunner.privateRun(TestRunner.java:617)
	at org.testng.TestRunner.run(TestRunner.java:498)
	at org.testng.SuiteRunner.runTest(SuiteRunner.java:329)
	at org.testng.SuiteRunner.runSequentially(SuiteRunner.java:324)
	at org.testng.SuiteRunner.privateRun(SuiteRunner.java:296)
	at org.testng.SuiteRunner.run(SuiteRunner.java:201)
	at org.testng.TestNG.createAndRunSuiteRunners(TestNG.java:915)
	at org.testng.TestNG.runSuitesLocally(TestNG.java:879)
	at org.testng.TestNG.run(TestNG.java:787)
	at org.testng.remote.RemoteTestNG.run(RemoteTestNG.java:75)
	at org.testng.remote.RemoteTestNG.main(RemoteTestNG.java:127)
]]>
            </full-stacktrace>
          </exception>
        </test-method>
        <test-method status="PASS" signature="setupMocksAndTargetForDefaultBehavior()" name="setupMocksAndTargetForDefaultBehavior" is-config="true" duration-ms="1" started-at="2010-02-08T15:37:28Z" finished-at="2010-02-08T15:37:28Z">
        </test-method>
        <test-method status="PASS" signature="shouldThrowBusinessExceptionIfDatabaseIsDown()" name="shouldThrowBusinessExceptionIfDatabaseIsDown" duration-ms="6" started-at="2010-02-08T15:37:28Z" finished-at="2010-02-08T15:37:28Z">
          <exception class="com.pillartech.blog.exception.AccountNotFoundException">
            <message>
              <![CDATA[Unable to find account due to underlying issue]]>
            </message>
            <full-stacktrace>
              <![CDATA[com.pillartech.blog.exception.AccountNotFoundException: Unable to find account due to underlying issue
	at com.pillartech.blog.LoginServiceImpl.findAccountByUsername(LoginServiceImpl.java:48)
	at com.pillartech.blog.LoginServiceImpl.login(LoginServiceImpl.java:22)
	at com.pillartech.blog.LoginServiceTest.shouldThrowBusinessExceptionIfDatabaseIsDown(LoginServiceTest.java:149)
	at sun.reflect.NativeMethodAccessorImpl.invoke0(Native Method)
	at sun.reflect.NativeMethodAccessorImpl.invoke(NativeMethodAccessorImpl.java:39)
	at sun.reflect.DelegatingMethodAccessorImpl.invoke(DelegatingMethodAccessorImpl.java:25)
	at java.lang.reflect.Method.invoke(Method.java:597)
	at org.testng.internal.MethodHelper.invokeMethod(MethodHelper.java:644)
	at org.testng.internal.Invoker.invokeMethod(Invoker.java:546)
	at org.testng.internal.Invoker.invokeTestMethod(Invoker.java:700)
	at org.testng.internal.Invoker.invokeTestMethods(Invoker.java:1002)
	at org.testng.internal.TestMethodWorker.invokeTestMethods(TestMethodWorker.java:137)
	at org.testng.internal.TestMethodWorker.run(TestMethodWorker.java:121)
	at org.testng.TestRunner.runWorkers(TestRunner.java:908)
	at org.testng.TestRunner.privateRun(TestRunner.java:617)
	at org.testng.TestRunner.run(TestRunner.java:498)
	at org.testng.SuiteRunner.runTest(SuiteRunner.java:329)
	at org.testng.SuiteRunner.runSequentially(SuiteRunner.java:324)
	at org.testng.SuiteRunner.privateRun(SuiteRunner.java:296)
	at org.testng.SuiteRunner.run(SuiteRunner.java:201)
	at org.testng.TestNG.createAndRunSuiteRunners(TestNG.java:915)
	at org.testng.TestNG.runSuitesLocally(TestNG.java:879)
	at org.testng.TestNG.run(TestNG.java:787)
	at org.testng.remote.RemoteTestNG.run(RemoteTestNG.java:75)
	at org.testng.remote.RemoteTestNG.main(RemoteTestNG.java:127)
Caused by: java.lang.RuntimeException
	at com.pillartech.blog.LoginServiceImpl.findAccountByUsername(LoginServiceImpl.java:41)
	... 24 more
]]>
            </full-stacktrace>
          </exception>
        </test-method>
      </class>
    </test>
  </suite>
</testng-results>
